<mujoco model="humanoid">
    <compiler angle="radian" inertiafromgeom="true"/>
    <default>
        <joint armature="1" damping="1"/>
        <geom conaffinity="1" condim="3" contype="1" margin="0.001" rgba="0.7 0.5 .3 1"/>
        <site rgba="0.7 0.5 0.3 1"/>
    </default>

    <asset>
        <texture builtin="flat" height="1278" mark="cross" markrgb="1 1 1" name="texgeom" random="0.01"
                 rgb1="0.8 0.6 0.4" rgb2="0.8 0.6 0.4" type="cube" width="127"/>
        <texture name="grid" type="2d" builtin="checker" rgb1=".1 .2 .3" rgb2=".2 .3 .4" width="300" height="300"
                 mark="edge" markrgb=".2 .3 .4"/>
        <material name="MatPlane" reflectance="0.2" texrepeat="1 1" texuniform="true" texture="grid"/>
        <material name="geom" texture="texgeom" texuniform="true"/>
    </asset>
    <worldbody>

        <body name="root" pos="0 0 0.9">
            <geom name="root" mass="6.0" pos="0 0 0.07" size="0.09" type="sphere"/>
            <site name="chull_p48" rgba='0 0 1 0' pos="0 -0.098 0.07" size="0.01" type="sphere"/>
            <site name="chull_p49" rgba='0 0 1 0' pos="0 0.098 0.07" size="0.01" type="sphere"/>
            <site name="chull_p50" rgba='0 0 1 0' pos="-0.098 0 0.07" size="0.01" type="sphere"/>
            <site name="chull_p51" rgba='0 0 1 0' pos="0.098 0 0.07" size="0.01" type="sphere"/>
            <camera name="back" pos="-3 0 1" xyaxes="0 -1 0 1 0 2" mode="trackcom"/>
            <camera name="side" pos="0 -3 1" xyaxes="1 0 0 0 1 2" mode="trackcom"/>
            <joint armature="0" damping="0" name="root" pos="0 0 0" range="-2.57 1.57" stiffness="0" type="free"/>
            <site name="joint_waist" pos="0 0 0.205" size="0.07" type="sphere"/>
            <site name="chull_p16" rgba='0 0 1 0' pos="0 -0.079 0.205" size="0.01" type="sphere"/>
            <site name="chull_p17" rgba='0 0 1 0' pos="0 0.079 0.205" size="0.01" type="sphere"/>
            <site name="chull_p46" rgba='0 0 1 0' pos="-0.079 0 0.205" size="0.01" type="sphere"/>
            <site name="chull_p47" rgba='0 0 1 0' pos="0.079 0 0.205" size="0.01" type="sphere"/>
            <site name="joint_front_x" rgba='1 0 0 1' pos="0.08 0 0.205" size="0.01 0.01 0.01" type="box"/>
            <body name="chest" pos="0 0 0.236151">
                <geom name="chest" mass="14.0" pos="0 0 0.12" size=".11" type="sphere"/>
                <site name="chull_p14" rgba='0 0 1 0' pos="0 -0.119 0.12" size="0.01" type="sphere"/>
                <site name="chull_p15" rgba='0 0 1 0' pos="0 0.119 0.12" size="0.01" type="sphere"/>
                <site name="chull_p44" rgba='0 0 1 0' pos="-0.119 0 0.12" size="0.01" type="sphere"/>
                <site name="chull_p45" rgba='0 0 1 0' pos="0.119 0 0.12" size="0.01" type="sphere"/>
                <joint limited="true" name="chest_x" axis="1 0 0" pos="0 0 0" range="-1.2 1.2" type="hinge"/>
                <joint limited="true" name="chest_y" axis="0 1 0" pos="0 0 0" range="-1.2 1.2" type="hinge"/>
                <joint limited="true" name="chest_z" axis="0 0 1" pos="0 0 0" range="-1.2 1.2" type="hinge"/>
                <body name="neck" pos="0 0 0.223894">
                    <geom name="neck" mass="2.0" pos="0 0 0.175" size=".1025" type="sphere"/>
                    <!--                    <site name="chull_p68" rgba='0 0 1 0' pos="0.097 0 0.14" size="0.01" type="sphere"/>-->
                    <!--                    <site name="chull_p69" rgba='0 0 1 0' pos="0.097 0 0.23" size="0.01" type="sphere"/>-->
                    <joint limited="true" name="neck_x" axis="1 0 0" pos="0 0 0" range="-1.0 1.0" type="hinge"/>
                    <joint limited="true" name="neck_y" axis="0 1 0" pos="0 0 0" range="-1.0 1.0" type="hinge"/>
                    <joint limited="true" name="neck_z" axis="0 0 1" pos="0 0 0" range="-1.0 1.0" type="hinge"/>
                    <site name="joint_neck" pos="0 0t 0.02" size="0.04" type="sphere"/>
                    <site name="chull_p01" rgba='0 0 1 0' pos="0 0 0.285" size="0.01" type="sphere"/>
                    <site name="chull_p32" rgba='0 0 1 0' pos="0 -0.11 0.25" size="0.01" type="sphere"/>
                    <site name="chull_p33" rgba='0 0 1 0' pos="0 0.11 0.25" size="0.01" type="sphere"/>
                    <site name="chull_p34" rgba='0 0 1 0' pos="-0.11 0 0.25" size="0.01" type="sphere"/>
                    <site name="chull_p35" rgba='0 0 1 0' pos="0.11 0 0.25" size="0.01" type="sphere"/>
                    <site name="chull_p73" rgba='0 0 1 0' pos="0.08 -0.08 0.26" size="0.01" type="sphere"/>
                    <site name="chull_p74" rgba='0 0 1 0' pos="0.08 0.08 0.26" size="0.01" type="sphere"/>
                    <site name="chull_p75" rgba='0 0 1 0' pos="-0.08 0.08 0.26" size="0.01" type="sphere"/>
                    <site name="chull_p76" rgba='0 0 1 0' pos="-0.08 -0.08 0.26" size="0.01" type="sphere"/>
                </body>
                <site name="right_clavicle" euler="-1.57 0 0" pos="-0.011 -0.095 0.24" size="0.045 0.025"
                      type="capsule"/>
                <body name="right_shoulder" pos="-0.02405 -0.18311 0.2435">
                    <geom fromto="0 0 -0.05 0 0 -0.23" name="right_shoulder" mass="1.5" size="0.045" type="capsule"/>
                    <site name="joint_right_shoulder" pos="0 0 0" size="0.04" type="sphere"/>
                    <site name="chull_p02" rgba='0 0 1 0' pos="0 -0.033 0.035" size="0.01" type="sphere"/>
                    <site name="chull_p03" rgba='0 0 1 0' pos="0 -0.06 -0.15" size="0.01" type="sphere"/>
                    <site name="chull_p04" rgba='0 0 1 0' pos="0 0.053 -0.15" size="0.01" type="sphere"/>
                    <site name="chull_p36" rgba='0 0 1 0' pos="-0.053 0 -0.15" size="0.01" type="sphere"/>
                    <site name="chull_p37" rgba='0 0 1 0' pos="0.053 0 -0.15" size="0.01" type="sphere"/>
                    <site name="chull_p77" rgba='0 0 1 0' pos="0.05 -0.06 -0.075" size="0.01" type="sphere"/>
                    <site name="chull_p81" rgba='0 0 1 0' pos="-0.05 -0.06 -0.075" size="0.01" type="sphere"/>

                    <joint limited="true" name="right_shoulder_x" axis="1 0 0" pos="0 0 0" range="-3.14 0.5"
                           type="hinge"/>
                    <joint limited="true" name="right_shoulder_y" axis="0 1 0" pos="0 0 0" range="-3.14 0.7"
                           type="hinge"/>
                    <joint limited="true" name="right_shoulder_z" axis="0 0 1" pos="0 0 0" range="-1.5 1.5"
                           type="hinge"/>
                    <body name="right_elbow" pos="0 0 -0.274788">
                        <geom fromto="0 0 -0.0525 0 0 -0.1875" name="right_elbow" mass="1.0" size="0.04"
                              type="capsule"/>
                        <joint limited="true" axis="0 -1 0" name="right_elbow" pos="0 0 0" range="0 2.8" type="hinge"/>
                        <site name="joint_right_elbow" pos="0 0 0" size="0.03" type="sphere"/>
                        <site name="chull_p65" rgba='0 0 1 0' pos="-0.05 0 0" size="0.01" type="sphere"/>
                        <site name="chull_p05" rgba='0 0 1 0' pos="0 -0.055 -0.125" size="0.01" type="sphere"/>
                        <site name="chull_p06" rgba='0 0 1 0' pos="0 0.049 -0.125" size="0.01" type="sphere"/>
                        <site name="chull_p38" rgba='0 0 1 0' pos="-0.049 0 -0.125" size="0.01" type="sphere"/>
                        <site name="chull_p39" rgba='0 0 1 0' pos="0.049 0 -0.125" size="0.01" type="sphere"/>
                        <site name="chull_p07" rgba='0 0 1 0' pos="0 0 -0.315" size="0.01" type="sphere"/>
                        <site name="chull_p71" rgba='0 0 1 0' pos="0 -0.055 -0.26" size="0.01" type="sphere"/>
                        <site name="chull_p91" rgba='0 0 1 0' pos="0.05 -0.02 -0.29" size="0.01" type="sphere"/>
                        <site name="chull_p92" rgba='0 0 1 0' pos="-0.05 -0.02 -0.29" size="0.01" type="sphere"/>
                        <geom name="right_wrist" mass="0.5" pos="0 0 -0.258947" size="0.04" type="sphere"/>
                    </body>
                </body>
                <site name="left_clavicle" euler="-1.57 0 0" pos="-0.011 0.095 0.24" size="0.045 0.025" type="capsule"/>
                <body name="left_shoulder" pos="-0.02405 0.18311 0.2435">
                    <site name="force_sensor:shoulder_left" pos="0 0 0" rgba="1 0 1 0.1" size="0.02 0.02 0.02"/>
                    <geom fromto="0 0 -0.05 0 0 -0.23" name="left_shoulder" mass="1.5" size="0.045" type="capsule"/>
                    <joint limited="true" name="left_shoulder_x" axis="1 0 0" pos="0 0 0" range="-0.5 3.14"
                           type="hinge"/>
                    <joint limited="true" name="left_shoulder_y" axis="0 1 0" pos="0 0 0" range="-3.14 0.7"
                           type="hinge"/>
                    <joint limited="true" name="left_shoulder_z" axis="0 0 1" pos="0 0 0" range="-1.5 1.5"
                           type="hinge"/>
                    <site name="joint_left_shoulder" pos="0 0 0" size="0.04" type="sphere"/>
                    <site name="chull_p08" rgba='0 0 1 0' pos="0 0.033 0.035" size="0.01" type="sphere"/>
                    <site name="chull_p09" rgba='0 0 1 0' pos="0 0.06 -0.15" size="0.01" type="sphere"/>
                    <site name="chull_p10" rgba='0 0 1 0' pos="0 -0.053 -0.15" size="0.01" type="sphere"/>
                    <site name="chull_p40" rgba='0 0 1 0' pos="-0.053 0 -0.15" size="0.01" type="sphere"/>
                    <site name="chull_p41" rgba='0 0 1 0' pos="0.053 0 -0.15" size="0.01" type="sphere"/>
                    <site name="chull_p78" rgba='0 0 1 0' pos="0.05 0.06 -0.075" size="0.01" type="sphere"/>
                    <site name="chull_p82" rgba='0 0 1 0' pos="-0.05 0.06 -0.075" size="0.01" type="sphere"/>
                    <body name="left_elbow" pos="0 0 -0.274788">
                        <geom fromto="0 0 -0.0525 0 0 -0.1875" name="left_elbow" mass="1.0" size="0.04" type="capsule"/>
                        <joint limited="true" axis="0 -1 0" name="left_elbow" pos="0 0 0" range="0 2.8" type="hinge"/>
                        <site name="joint_left_elbow" pos="0 0 0" size="0.03" type="sphere"/>
                        <site name="chull_p64" rgba='0 0 1 0' pos="-0.05 0 0" size="0.01" type="sphere"/>
                        <site name="chull_p11" rgba='0 0 1 0' pos="0 0.055 -0.125" size="0.01" type="sphere"/>
                        <site name="chull_p42" rgba='0 0 1 0' pos="-0.049 0 -0.125" size="0.01" type="sphere"/>
                        <site name="chull_p43" rgba='0 0 1 0' pos="0.049 0 -0.125" size="0.01" type="sphere"/>
                        <site name="chull_p12" rgba='0 0 1 0' pos="0 -0.049 -0.125" size="0.01" type="sphere"/>
                        <site name="chull_p13" rgba='0 0 1 0' pos="0 0 -0.315" size="0.01" type="sphere"/>
                        <site name="chull_p70" rgba='0 0 1 0' pos="0 0.055 -0.26" size="0.01" type="sphere"/>
                        <site name="chull_p89" rgba='0 0 1 0' pos="0.05 0.02 -0.29" size="0.01" type="sphere"/>
                        <site name="chull_p90" rgba='0 0 1 0' pos="-0.05 0.02 -0.29" size="0.01" type="sphere"/>
                        <geom name="left_wrist" mass="0.5" pos="0 0 -0.258947" size="0.04" type="sphere"/>
                        <!--geom name="box" mass="0.5" pos="0 -0.182 -0.258947" rgba = "1 1 1 1" size="0.15 0.15 0.12" type="box"/-->
                    </body>
                </body>
            </body>
            <body name="right_hip" pos="0 -0.084887 0">
                <geom fromto="0 0 -0.06 0 0 -0.36" name="right_hip" mass="4.5" size="0.055" type="capsule"/>
                <site name="joint_right_hip" pos="0 0 0" size="0.045" type="sphere"/>
                <site name="chull_p18" rgba='0 0 1 0' pos="0 -0.04 0.037" size="0.01" type="sphere"/>
                <site name="chull_p19" rgba='0 0 1 0' pos="0 -0.064 -0.2" size="0.01" type="sphere"/>
                <site name="chull_p20" rgba='0 0 1 0' pos="0 0.064 -0.2" size="0.01" type="sphere"/>
                <site name="chull_p52" rgba='0 0 1 0' pos="-0.064 0 -0.2" size="0.01" type="sphere"/>
                <site name="chull_p53" rgba='0 0 1 0' pos="0.064 0 -0.2" size="0.01" type="sphere"/>
                <joint limited="true" name="right_hip_x" axis="1 0 0" pos="0 0 0" range="-1.2 1.2" type="hinge"/>
                <joint limited="true" name="right_hip_y" axis="0 1 0" pos="0 0 0" range="-2.57 1.57" type="hinge"/>
                <joint limited="true" name="right_hip_z" axis="0 0 1" pos="0 0 0" range=" -1.0 1.0" type="hinge"/>
                <body name="right_knee" pos="0 0 -0.421546">
                    <geom fromto="0 0 -0.045 0 0 -0.355" name="right_knee" mass="3.0" size="0.05" type="capsule"/>
                    <site name="joint_right_knee" pos="0 0 0" size="0.035" type="sphere"/>
                    <site name="chull_p66" rgba='0 0 1 0' pos="0.035 0 0" size="0.01" type="sphere"/>
                    <site name="chull_p21" rgba='0 0 1 0' pos="0 0.059 -0.18" size="0.01" type="sphere"/>
                    <site name="chull_p22" rgba='0 0 1 0' pos="0 -0.059 -0.18" size="0.01" type="sphere"/>
                    <site name="chull_p54" rgba='0 0 1 0' pos="-0.059 0 -0.18" size="0.01" type="sphere"/>
                    <site name="chull_p55" rgba='0 0 1 0' pos="0.059 0 -0.18" size="0.01" type="sphere"/>
                    <joint limited="true" axis="0 -1 0" name="right_knee" pos="0 0 0" range="-2.7 0.0" type="hinge"/>
                    <body name="right_ankle" pos="0 0 -0.40987">
                        <joint limited="true" name="right_ankle_x" axis="1 0 0" pos="0 0 0" range="-1.0 1.0"
                               type="hinge"/>
                        <joint limited="true" name="right_ankle_y" axis="0 1 0" pos="0 0 0" range="-1.0 1.57"
                               type="hinge"/>
                        <joint limited="true" name="right_ankle_z" axis="0 0 1" pos="0 0 0" range="-1.0 1.0"
                               type="hinge"/>
                        <site name="joint_right_ankle" pos="0 0 0" size="0.04" type="sphere"/>
                        <site name="chull_p23" rgba='0 0 1 0' pos="0 -0.058 -0.05" size="0.01"
                              type="sphere"/> <!-- 0.139 /-->
                        <site name="chull_p24" rgba='0 0 1 0' pos="0 0.056 -0.05" size="0.01" type="sphere"/>
                        <site name="chull_p56" rgba='0 0 1 0' pos="-0.057 0 -0.05" size="0.01" type="sphere"/>
                        <site name="chull_p57" rgba='0 0 1 0' pos="0.15 0 -0.05" size="0.01" type="sphere"/>
                        <site name="chull_p79" rgba='0 0 1 0' pos="0.14 -0.05 -0.05" size="0.01" type="sphere"/>
                        <site name="chull_p83" rgba='0 0 1 0' pos="0.14 0.05 -0.05" size="0.01" type="sphere"/>
                        <site name="chull_p84" rgba='0 0 1 0' pos="-0.05 -0.05 -0.05" size="0.01" type="sphere"/>
                        <site name="chull_p85" rgba='0 0 1 0' pos="-0.05 0.05 -0.05" size="0.01" type="sphere"/>
                        <geom name="right_ankle" mass="1.0" pos="0.045 0 -0.0225" size="0.0885 0.045 0.0275"
                              type="box"/>
                    </body>
                </body>
            </body>
            <body name="left_hip" pos="0 0.084887 0">
                <geom fromto="0 0 -0.06 0 0 -0.36" name="left_hip" mass="4.5" size="0.055" type="capsule"/>
                <site name="joint_left_hip" pos="0 0 0" size="0.045" type="sphere"/>
                <site name="chull_p25" rgba='0 0 1 0' pos="0 0.04 0.037" size="0.01" type="sphere"/>
                <site name="chull_p26" rgba='0 0 1 0' pos="0 -0.064 -0.2" size="0.01" type="sphere"/>
                <site name="chull_p27" rgba='0 0 1 0' pos="0 0.064 -0.2" size="0.01" type="sphere"/>
                <site name="chull_p58" rgba='0 0 1 0' pos="-0.064 0 -0.2" size="0.01" type="sphere"/>
                <site name="chull_p59" rgba='0 0 1 0' pos="0.064 0 -0.2" size="0.01" type="sphere"/>
                <joint limited="true" name="left_hip_x" axis="1 0 0" pos="0 0 0" range="-1.2 1.2" type="hinge"/>
                <joint limited="true" name="left_hip_y" axis="0 1 0" pos="0 0 0" range="-2.57 1.57" type="hinge"/>
                <joint limited="true" name="left_hip_z" axis="0 0 1" pos="0 0 0" range="-1.0 1.0" type="hinge"/>
                <body name="left_knee" pos="0 0 -0.421546">
                    <geom fromto="0 0 -0.045 0 0 -0.355" name="left_knee" mass="3.0" size="0.05" type="capsule"/>
                    <site name="joint_left_knee" pos="0 0 0" size="0.035" type="sphere"/>
                    <site name="chull_p67" rgba='0 0 1 0' pos="0.035 0 0" size="0.01" type="sphere"/>
                    <site name="chull_p28" rgba='0 0 1 0' pos="0 -0.059 -0.18" size="0.01" type="sphere"/>
                    <site name="chull_p29" rgba='0 0 1 0' pos="0 0.059 -0.18" size="0.01" type="sphere"/>
                    <site name="chull_p60" rgba='0 0 1 0' pos="-0.059 0 -0.18" size="0.01" type="sphere"/>
                    <site name="chull_p61" rgba='0 0 1 0' pos="0.059 0 -0.18" size="0.01" type="sphere"/>
                    <joint limited="true" axis="0 -1 0" name="left_knee" pos="0 0 0" range="-2.7 0.0" type="hinge"/>
                    <body name="left_ankle" pos="0 0 -0.40987">
                        <joint limited="true" name="left_ankle_x" axis="1 0 0" pos="0 0 0" range="-1.0 1.0"
                               type="hinge"/>
                        <joint limited="true" name="left_ankle_y" axis="0 1 0" pos="0 0 0" range="-1.0 1.57"
                               type="hinge"/>
                        <joint limited="true" name="left_ankle_z" axis="0 0 1" pos="0 0 0" range="-1.0 1.0"
                               type="hinge"/>
                        <site name="joint_left_ankle" pos="0 0 0" size="0.04" type="sphere"/>
                        <site name="chull_p30" rgba='0 0 1 0' pos="0 -0.058 -0.05" size="0.01"
                              type="sphere"/> <!-- 0.139 -->
                        <site name="chull_p31" rgba='0 0 1 0' pos="0 0.056 -0.05" size="0.01" type="sphere"/>
                        <site name="chull_p62" rgba='0 0 1 0' pos="-0.057 0 -0.05" size="0.01" type="sphere"/>
                        <site name="chull_p63" rgba='0 0 1 0' pos="0.15 0 -0.05" size="0.01" type="sphere"/>
                        <site name="chull_p80" rgba='0 0 1 0' pos="0.14 0.05 -0.05" size="0.01" type="sphere"/>
                        <site name="chull_p86" rgba='0 0 1 0' pos="0.14 -0.05 -0.05" size="0.01" type="sphere"/>
                        <site name="chull_p87" rgba='0 0 1 0' pos="-0.05 0.05 -0.05" size="0.01" type="sphere"/>
                        <site name="chull_p88" rgba='0 0 1 0' pos="-0.05 -0.05 -0.05" size="0.01" type="sphere"/>
                        <geom name="left_ankle" mass="1.0" pos="0.045 0 -0.0225" size="0.0885 0.045 0.0275" type="box"/>
                    </body>
                </body>
            </body>
        </body>
    </worldbody>

    <contact>
        <exclude body1="right_hip" body2="root"/>
        <exclude body1="left_hip" body2="root"/>
        <exclude body1="right_hip" body2="right_knee"/>
        <exclude body1="left_hip" body2="left_knee"/>
        <exclude body1="right_knee" body2="right_ankle"/>
        <exclude body1="left_knee" body2="left_ankle"/>
        <exclude body1="right_elbow" body2="right_shoulder"/>
        <exclude body1="left_elbow" body2="left_shoulder"/>
    </contact>

</mujoco>
